data/online_replay/msft_lobster_replay.csv
timestamp,event_type,order_id,side,type,price,quantity
34200074,order,16135101,Buy,Limit,31,300
34200202,order,16166153,Sell,Limit,31,100
34200202,order,16166187,Sell,Limit,31,100
34200205,order,16167006,Sell,Limit,31,100
34200211,order,16168549,Sell,Limit,31,100
34200317,order,7326600,Buy,Limit,31,5
34200317,order,3581980,Sell,Limit,31,28
34200317,order,3906511,Sell,Limit,31,100
34200317,order,4743470,Sell,Limit,31,100
34200317,order,4745892,Sell,Limit,31,267
34200317,order,4748779,Sell,Limit,31,2111
34200317,order,4749881,Sell,Limit,31,1867
34200317,order,4751686,Sell,Limit,31,29
34200317,order,4752136,Sell,Limit,31,87
34200317,order,4752217,Sell,Limit,31,250
34200317,order,4754975,Sell,Limit,31,141
34200317,order,4756682,Sell,Limit,31,100
34200317,order,4756755,Sell,Limit,31,1008
34200317,order,4768364,Sell,Limit,31,889
34200317,order,4885371,Sell,Limit,31,14
34200317,order,4885495,Sell,Limit,31,2700
34200317,order,4886246,Sell,Limit,31,120
34200317,order,4886247,Sell,Limit,31,700
34200317,order,4886471,Sell,Limit,31,46
34200317,order,4886998,Sell,Limit,31,200
34200317,order,4887141,Sell,Limit,31,170
34200317,order,4887302,Sell,Limit,31,100
34200317,order,5980692,Sell,Limit,31,200
34200317,order,5980693,Sell,Limit,31,50
34200317,order,5980695,Sell,Limit,31,499
34200317,order,5980697,Sell,Limit,31,154
34200317,order,5980698,Sell,Limit,31,250
34200317,order,5980699,Sell,Limit,31,100
34200317,order,5980702,Sell,Limit,31,100
34200317,order,5980703,Sell,Limit,31,200
34200317,order,5980704,Sell,Limit,31,130
34200317,order,5980708,Sell,Limit,31,150
34200317,order,5980709,Sell,Limit,31,202
34200317,order,5980710,Sell,Limit,31,1000
34200317,order,5980712,Sell,Limit,31,1000
34200317,order,6016695,Sell,Limit,31,216
34200317,order,7552907,Sell,Limit,31,300
34200317,order,8589322,Sell,Limit,31,5500
34200317,order,9940243,Sell,Limit,31,2000
34200317,order,10030243,Sell,Limit,31,200
34200317,order,10562940,Sell,Limit,31,100
34200317,order,12644416,Sell,Limit,31,200
34200317,order,12687322,Sell,Limit,31,1100
34200317,order,12921845,Sell,Limit,31,150
34200317,order,12991178,Sell,Limit,31,100
34200319,order,16190592,Sell,Limit,31,100
34200319,order,16190619,Sell,Limit,31,100
34200324,order,16192040,Sell,Limit,31,1200
34200330,order,16192945,Sell,Limit,31,100
34200330,order,16192966,Sell,Limit,31,100
34200353,order,16197394,Buy,Limit,31,100
34200362,order,16199225,Buy,Limit,31,100
34200366,order,16200228,Sell,Limit,31,100
34200481,order,16224419,Buy,Limit,31,100
34200609,order,16248287,Sell,Limit,31,100
34200865,order,16288197,Sell,Limit,31,33
34200900,order,16292948,Sell,Limit,31,33
34200900,order,16292963,Sell,Limit,31,100
34200936,order,16298656,Buy,Limit,31,267
34200936,order,16298663,Buy,Limit,31,3000
34200936,order,16298681,Buy,Limit,31,100
34200936,order,16298686,Buy,Limit,31,100
34200936,order,16298690,Buy,Limit,31,100
34200936,order,16298714,Buy,Limit,31,100
34201051,order,16317947,Buy,Limit,31,3000
34201084,order,16323003,Sell,Limit,31,400
34201146,order,16333185,Buy,Limit,31,300
34201146,order,16333190,Buy,Limit,31,100
34201182,order,16338595,Buy,Limit,31,9
34201398,order,16365900,Buy,Limit,31,300
34201629,order,16387882,Sell,Limit,31,3000
34201629,order,16387886,Sell,Limit,31,100
34201629,order,16387891,Sell,Limit,31,3000
34201629,order,16387892,Sell,Limit,31,100
34201635,order,16388500,Sell,Limit,31,3000
34201635,order,16388505,Sell,Limit,31,100
34201745,order,16397137,Sell,Limit,31,200
34202030,order,16415403,Sell,Limit,31,3000
34202030,order,16415404,Sell,Limit,31,100
34202030,order,16415406,Sell,Limit,31,3000
34202030,order,16415409,Sell,Limit,31,100
34202030,order,16415411,Sell,Limit,31,100
34202032,order,16415630,Sell,Limit,31,3000
34202032,order,16415632,Sell,Limit,31,100
34202032,order,16415634,Sell,Limit,31,3000
34202032,order,16415639,Sell,Limit,31,100
34202208,order,16433322,Buy,Limit,31,100
34202446,order,16474699,Buy,Limit,31,100
34202480,order,16477996,Sell,Limit,31,3000
34202480,order,16477998,Sell,Limit,31,100
34202481,order,16478159,Sell,Limit,31,3000
34202481,order,16478166,Sell,Limit,31,100
34202481,order,16478174,Sell,Limit,31,100
34202786,order,16507754,Sell,Limit,31,200
34202789,order,16508027,Buy,Limit,31,3000
34202789,order,16508028,Buy,Limit,31,100
34202796,order,16508787,Buy,Limit,31,3000
34202796,order,16508789,Buy,Limit,31,100
34202811,order,16510061,Buy,Limit,31,100
34202814,order,16510390,Buy,Limit,31,3000
34202814,order,16510397,Buy,Limit,31,3000
34202952,order,16522272,Buy,Limit,31,100
34203042,order,16531141,Sell,Limit,31,3000
34203042,order,16531143,Sell,Limit,31,100
34203192,order,16544714,Sell,Limit,31,400
34203550,order,16576783,Sell,Limit,31,3000
34203550,order,16576787,Sell,Limit,31,100
34203550,order,16576792,Sell,Limit,31,100
34203550,order,16576799,Sell,Limit,31,100
34203699,order,16592339,Sell,Limit,31,100
34203717,order,16594939,Buy,Limit,31,3000
34203717,order,16594944,Buy,Limit,31,3000
34203721,order,16595357,Sell,Limit,31,3000
34203721,order,16595361,Sell,Limit,31,100
34203722,order,16595382,Sell,Limit,31,3000
34203722,order,16595387,Sell,Limit,31,100
34203722,order,16595399,Sell,Limit,31,100
34203722,order,16595416,Sell,Limit,31,100
34203741,order,16597052,Buy,Limit,31,3000
34203741,order,16597055,Buy,Limit,31,3000
34203744,order,16597313,Buy,Limit,31,100
34203745,order,16597334,Buy,Limit,31,3000
34203745,order,16597374,Buy,Limit,31,100
34203812,order,16603416,Sell,Limit,31,499
34203909,order,16613317,Sell,Limit,31,575
34204268,order,16648137,Sell,Limit,31,3000
34204269,order,16648205,Buy,Limit,31,300
34204269,order,16648212,Buy,Limit,31,3000
34204269,order,16648216,Buy,Limit,31,100
34204269,order,16648225,Buy,Limit,31,300
34204273,order,16648822,Buy,Limit,31,100
34204273,order,16648824,Buy,Limit,31,500
34204987,order,16712588,Buy,Limit,31,3000
34204987,order,16712590,Buy,Limit,31,100
34204988,order,16712705,Buy,Limit,31,2200
34204988,order,16712706,Buy,Limit,31,100
34204988,order,16712712,Buy,Limit,31,3000
34204989,order,16712714,Buy,Limit,31,100
34204994,order,16713156,Buy,Limit,31,2200
34204994,order,16713161,Buy,Limit,31,100
34205014,order,16715119,Buy,Limit,31,100
34205021,order,16715829,Buy,Limit,31,100
34205021,order,16715842,Buy,Limit,31,2200
34205032,order,16716812,Buy,Limit,31,100
34205032,order,16716814,Buy,Limit,31,2200
34205032,order,16716817,Buy,Limit,31,100
34205034,order,16716943,Sell,Limit,31,100
34205034,order,16716957,Sell,Limit,31,100
34205037,order,16717232,Buy,Limit,31,100
34205071,order,16720518,Sell,Limit,31,3000
34205071,order,16720521,Sell,Limit,31,100
34205071,order,16720527,Sell,Limit,31,100
34205072,order,16720532,Sell,Limit,31,100
34205072,order,16720537,Sell,Limit,31,100
34205272,order,16742252,Sell,Limit,31,900
34205272,order,16742253,Sell,Limit,31,2200
34205272,order,16742257,Sell,Limit,31,500
34205272,order,16742258,Sell,Limit,31,2200
34205272,order,16742263,Sell,Limit,31,3000
34205275,order,16742592,Buy,Limit,31,300
34205276,order,16742645,Sell,Limit,31,400
34205765,order,16779113,Buy,Limit,31,2200
34205765,order,16779142,Buy,Limit,31,100
34205765,order,16779146,Buy,Limit,31,2200
34205765,order,16779170,Buy,Limit,31,100
34205777,order,16782889,Sell,Limit,31,100
34205777,order,16782915,Sell,Limit,31,100
34205779,order,16783171,Sell,Limit,31,1200
34205784,order,16783675,Sell,Limit,31,100
34205788,order,16783976,Sell,Limit,31,100
34205789,order,16784021,Sell,Limit,31,1200
34205790,order,16784101,Sell,Limit,31,100
34205790,order,16784143,Sell,Limit,31,1200
34206144,order,16810689,Sell,Limit,31,100
34206144,order,16810691,Sell,Limit,31,100
34206148,order,16810810,Sell,Limit,31,100
34206274,order,16817264,Sell,Limit,31,2200
34206274,order,16817270,Sell,Limit,31,100
34206275,order,16817276,Sell,Limit,31,300
34206275,order,16817278,Sell,Limit,31,3000
34206275,order,16817284,Sell,Limit,31,100
34206275,order,16817298,Sell,Limit,31,300
34206275,order,16817327,Sell,Limit,31,100
34206279,order,16817502,Sell,Limit,31,2200
34206279,order,16817504,Sell,Limit,31,100
34206279,order,16817506,Sell,Limit,31,100
